# Utilizzo di try, except e finally

Il blocco `try...except...finally` è uno strumento potente in Python per gestire eccezioni in modo ordinato e prevedibile. Questo blocco consente di separare il codice che potrebbe generare errori, la logica per gestire tali errori e le operazioni che devono essere eseguite indipendentemente dall'esito.

## Struttura del Blocco

- **`try`**: Contiene il codice che potrebbe generare un'eccezione. Se non si verifica alcuna eccezione, il blocco `except` viene saltato e il programma prosegue senza problemi.
- **`except`**: Esegue del codice se un'eccezione viene generata nel blocco `try`. È possibile specificare il tipo di eccezione da catturare.
- **`finally`**: Contiene codice che viene eseguito indipendentemente dal fatto che un'eccezione sia stata generata o meno. È utile per operazioni di pulizia, come chiudere file o connessioni.

## Esempi

### Esempio Base di Try...Except

Un esempio semplice di gestione delle eccezioni:

```python
x: int = int(input("Inserisci un numero: "))
try:
    risultato: int = 10 / x
    print(f"Il risultato è {risultato}")
except ZeroDivisionError:
    print("Non puoi dividere per zero!")
```

### Utilizzo del Blocco Finally

Il blocco `finally` è utile quando è necessario eseguire operazioni indipendentemente dal successo o dal fallimento del codice nel blocco `try`. Ad esempio:

```python
file = open("dati.txt", "w")
try:
    file.write("Scrittura nel file.")
except IOError:
    print("Errore durante la scrittura nel file.")
finally:
    file.close()
    print("File chiuso.")
```

In questo esempio, il file viene chiuso indipendentemente dal fatto che l'operazione di scrittura abbia avuto successo.

### Quando NON Usare Finally

Il blocco `finally` non è sempre necessario. Evitalo quando non ci sono risorse da liberare o operazioni da garantire. Ad esempio:

```python
try:
    numero = int(input("Inserisci un numero: "))
    print(f"Hai inserito {numero}.")
except ValueError:
    print("Errore: non è un numero valido.")
```

In questo caso, non c'è bisogno del blocco `finally` poiché non ci sono risorse da rilasciare.

## Più Except

È possibile avere più blocchi `except` per gestire diversi tipi di eccezioni. Ad esempio:

```python
try:
    valore = int(input("Inserisci un numero: "))
    risultato = 10 / valore
except ValueError:
    print("Errore: valore non valido.")
except ZeroDivisionError:
    print("Errore: divisione per zero.")
finally:
    print("Esecuzione completata.")
```

Qui, ogni tipo di errore viene gestito in modo specifico, e il blocco `finally` assicura che il messaggio "Esecuzione completata" venga stampato.

## Considerazioni Finali

- Usa `finally` solo quando è essenziale garantire l'esecuzione di un'operazione, come la chiusura di risorse.
- Specifica i tipi di eccezioni nel blocco `except` quando possibile, per evitare di catturare errori inattesi che non sono rilevanti.
